2025-06-15 01:26:22,293 INFO    MainThread:3068343 [wandb_setup.py:_flush():68] Current SDK version is 0.19.6
2025-06-15 01:26:22,293 INFO    MainThread:3068343 [wandb_setup.py:_flush():68] Configure stats pid to 3068343
2025-06-15 01:26:22,293 INFO    MainThread:3068343 [wandb_setup.py:_flush():68] Loading settings from /root/.config/wandb/settings
2025-06-15 01:26:22,293 INFO    MainThread:3068343 [wandb_setup.py:_flush():68] Loading settings from /root/LLM-for-legal-frauds/contract_sft/CodingProject4/wandb/settings
2025-06-15 01:26:22,293 INFO    MainThread:3068343 [wandb_setup.py:_flush():68] Loading settings from environment variables
2025-06-15 01:26:22,293 INFO    MainThread:3068343 [wandb_init.py:setup_run_log_directory():637] Logging user logs to /root/LLM-for-legal-frauds/contract_sft/CodingProject4/wandb/run-20250615_012622-7fqc1bld/logs/debug.log
2025-06-15 01:26:22,293 INFO    MainThread:3068343 [wandb_init.py:setup_run_log_directory():638] Logging internal logs to /root/LLM-for-legal-frauds/contract_sft/CodingProject4/wandb/run-20250615_012622-7fqc1bld/logs/debug-internal.log
2025-06-15 01:26:22,294 INFO    MainThread:3068343 [wandb_init.py:init():756] calling init triggers
2025-06-15 01:26:22,294 INFO    MainThread:3068343 [wandb_init.py:init():761] wandb.init called with sweep_config: {}
config: {'_wandb': {}}
2025-06-15 01:26:22,294 INFO    MainThread:3068343 [wandb_init.py:init():789] starting backend
2025-06-15 01:26:22,509 INFO    MainThread:3068343 [wandb_init.py:init():793] sending inform_init request
2025-06-15 01:26:22,514 INFO    MainThread:3068343 [backend.py:_multiprocessing_setup():97] multiprocessing start_methods=fork,spawn,forkserver, using: spawn
2025-06-15 01:26:22,515 INFO    MainThread:3068343 [wandb_init.py:init():808] backend started and connected
2025-06-15 01:26:22,517 INFO    MainThread:3068343 [wandb_init.py:init():901] updated telemetry
2025-06-15 01:26:22,529 INFO    MainThread:3068343 [wandb_init.py:init():936] communicating run to backend with 90.0 second timeout
2025-06-15 01:26:53,495 INFO    Thread-4 (wrapped_target):3068343 [retry.py:__call__():175] Retry attempt failed:
Traceback (most recent call last):
  File "/root/miniconda3/envs/aimo/lib/python3.10/site-packages/urllib3/connection.py", line 198, in _new_conn
    sock = connection.create_connection(
  File "/root/miniconda3/envs/aimo/lib/python3.10/site-packages/urllib3/util/connection.py", line 85, in create_connection
    raise err
  File "/root/miniconda3/envs/aimo/lib/python3.10/site-packages/urllib3/util/connection.py", line 73, in create_connection
    sock.connect(sa)
TimeoutError: timed out

The above exception was the direct cause of the following exception:

Traceback (most recent call last):
  File "/root/miniconda3/envs/aimo/lib/python3.10/site-packages/urllib3/connectionpool.py", line 787, in urlopen
    response = self._make_request(
  File "/root/miniconda3/envs/aimo/lib/python3.10/site-packages/urllib3/connectionpool.py", line 488, in _make_request
    raise new_e
  File "/root/miniconda3/envs/aimo/lib/python3.10/site-packages/urllib3/connectionpool.py", line 464, in _make_request
    self._validate_conn(conn)
  File "/root/miniconda3/envs/aimo/lib/python3.10/site-packages/urllib3/connectionpool.py", line 1093, in _validate_conn
    conn.connect()
  File "/root/miniconda3/envs/aimo/lib/python3.10/site-packages/urllib3/connection.py", line 704, in connect
    self.sock = sock = self._new_conn()
  File "/root/miniconda3/envs/aimo/lib/python3.10/site-packages/urllib3/connection.py", line 207, in _new_conn
    raise ConnectTimeoutError(
urllib3.exceptions.ConnectTimeoutError: (<urllib3.connection.HTTPSConnection object at 0x7f9f9855ab00>, 'Connection to api.wandb.ai timed out. (connect timeout=20)')

The above exception was the direct cause of the following exception:

Traceback (most recent call last):
  File "/root/miniconda3/envs/aimo/lib/python3.10/site-packages/requests/adapters.py", line 667, in send
    resp = conn.urlopen(
  File "/root/miniconda3/envs/aimo/lib/python3.10/site-packages/urllib3/connectionpool.py", line 841, in urlopen
    retries = retries.increment(
  File "/root/miniconda3/envs/aimo/lib/python3.10/site-packages/urllib3/util/retry.py", line 519, in increment
    raise MaxRetryError(_pool, url, reason) from reason  # type: ignore[arg-type]
urllib3.exceptions.MaxRetryError: HTTPSConnectionPool(host='api.wandb.ai', port=443): Max retries exceeded with url: /graphql (Caused by ConnectTimeoutError(<urllib3.connection.HTTPSConnection object at 0x7f9f9855ab00>, 'Connection to api.wandb.ai timed out. (connect timeout=20)'))

During handling of the above exception, another exception occurred:

Traceback (most recent call last):
  File "/root/miniconda3/envs/aimo/lib/python3.10/site-packages/wandb/sdk/lib/retry.py", line 134, in __call__
    result = self._call_fn(*args, **kwargs)
  File "/root/miniconda3/envs/aimo/lib/python3.10/site-packages/wandb/sdk/internal/internal_api.py", line 396, in execute
    return self.client.execute(*args, **kwargs)  # type: ignore
  File "/root/miniconda3/envs/aimo/lib/python3.10/site-packages/wandb/vendor/gql-0.2.0/wandb_gql/client.py", line 52, in execute
    result = self._get_result(document, *args, **kwargs)
  File "/root/miniconda3/envs/aimo/lib/python3.10/site-packages/wandb/vendor/gql-0.2.0/wandb_gql/client.py", line 60, in _get_result
    return self.transport.execute(document, *args, **kwargs)
  File "/root/miniconda3/envs/aimo/lib/python3.10/site-packages/wandb/sdk/lib/gql_request.py", line 58, in execute
    request = self.session.post(self.url, **post_args)
  File "/root/miniconda3/envs/aimo/lib/python3.10/site-packages/requests/sessions.py", line 637, in post
    return self.request("POST", url, data=data, json=json, **kwargs)
  File "/root/miniconda3/envs/aimo/lib/python3.10/site-packages/requests/sessions.py", line 589, in request
    resp = self.send(prep, **send_kwargs)
  File "/root/miniconda3/envs/aimo/lib/python3.10/site-packages/requests/sessions.py", line 703, in send
    r = adapter.send(request, **kwargs)
  File "/root/miniconda3/envs/aimo/lib/python3.10/site-packages/requests/adapters.py", line 688, in send
    raise ConnectTimeout(e, request=request)
requests.exceptions.ConnectTimeout: HTTPSConnectionPool(host='api.wandb.ai', port=443): Max retries exceeded with url: /graphql (Caused by ConnectTimeoutError(<urllib3.connection.HTTPSConnection object at 0x7f9f9855ab00>, 'Connection to api.wandb.ai timed out. (connect timeout=20)'))
2025-06-15 01:27:52,553 ERROR   MainThread:3068343 [wandb_init.py:init():1481] error in wandb.init()
Traceback (most recent call last):
  File "/root/miniconda3/envs/aimo/lib/python3.10/site-packages/wandb/sdk/wandb_init.py", line 1471, in init
    return wi.init(run_settings, run_config)
  File "/root/miniconda3/envs/aimo/lib/python3.10/site-packages/wandb/sdk/wandb_init.py", line 960, in init
    raise CommError(
wandb.errors.errors.CommError: Run initialization has timed out after 90.0 sec. Please try increasing the timeout with the `init_timeout` setting: `wandb.init(settings=wandb.Settings(init_timeout=120))`.
2025-06-15 01:27:52,566 WARNING MsgRouterThr:3068343 [router.py:message_loop():75] message_loop has been closed
